Workbook

Sheet SP List Extract
A1: ID | B1: Item Type | C1: Item Name | D1: PwC Owner | E1: Target Wave | F1: Actual Wave | G1: Design | H1: Build | I1: Test | J1: Sign-Off Requested | K1: Sign-Off Statu | L1: Nidhi Reviewed | M1: Nidhi's Feedback Incorporated | N1: Short Description | O1: Owner (NFP) | P1: Original Disposition (SOW) | Q1: Final Disposition Decision | R1: Status | S1: Target Build Date | T1: On Hold Reason | U1: Notes | V1: Story ID | W1: Target UAT Date | X1: Associated Aon Catalog Item (Adopt / Adapt) | Y1: Owner (Aon) | Z1: Design Session Date | AA1: Scope Changes | AB1: UAT Testers | AC1: Catalog Structure | AD1: Latest Update | AE1: Design Status | AF1: Design Planned Date | AG1: Design Forecasted Date | AH1: Design Actual Date | AI1: Build Status | AJ1: Build Planned Date | AK1: Build Forecasted Date | AL1: Build Actual Date | AM1: Test Status | AN1: Test Planned Date | AO1: Test Forecasted Date | AP1: Test Actual Date | AQ1: Deployed? | AR1: Deployed Planned Date | AS1: Deployed Forecasted Date | AT1: Deployed Actual Date | AU1: Order Guide Relation? | AV1: Onboarding Order Guide? | AW1: Missing / Placeholder Info | AX1: Currently Fulfilled by NFP SD? | AY1: Core Data Dependency | AZ1: RITM + Assignment Group | BA1: Item Type2 | BB1: Path
A2: CA001 | B2: Custom Application | C2: Primary Email Domain | D2: Javier | E2: 1.1 | F2: 1.1 | G2: Complete | H2: Complete | I2: Complete | J2: Done (08/31) | K2: Pending | N2: Custom application (with a custom table), nonscoped, that holds the primary email domain structure / format | O2: Antowan Jones | P2: Redesign | Q2: Redesign | R2: UAT In Progress | S2: 46227 | U2: User selects payroll company code during onboarding​. System presents available email domains​. Workflow determines email format and passes data to AD/Azure​. Managed via catalog item allowing add/update/deactivate actions | V2: STRY0146631 | W2: 46234 | AE2: Complete | AF2: 46234 | AG2: 46216 | AH2: 46216 | AI2: Complete | AJ2: 46241 | AK2: 46241 | AL2: 46220 | AM2: Not Started | AN2: 46247 | AO2: 46247 | AP2: 46227 | AQ2: Not Started | AR2: 46295 | AS2: 46295 | AU2: N/a | BA2: Item | BB2: sites/ext-AonNFPIntegration/Lists/ITSM Integration InScope Inventory
A3: INT001 | B3: Integration | C3: NFP Connect | D3: Javier | E3: 1.1 | F3: 1.1 | G3: Complete | H3: Complete | I3: In Progress | J3: Not Started | K3: Not Started | N3: Allows NFP Connect users (NFP Benefits Team – external users) to create incidents for NFP Connect issues they are facing. | O3: JP Subramaniam, Matt Fergo, Balajiprasad Ramesh | P3: Redesign | Q3: Redesign | R3: UAT In Progress | S3: 46232 | V3: STRY0146546 | W3: 46239 | AB3: • JP Subramaniam • Matt Fergo • Balajiprasad Ramesh • KamalNath Mudigati • Shashank Karanje | AE3: Complete | AF3: 46234 | AG3: 46227 | AH3: 46227 | AI3: Complete | AJ3: 46241 | AK3: 46241 | AL3: 46230 | AM3: Not Started | AN3: 46247 | AO3: 46247 | AP3: 46239 | AQ3: Not Started | AR3: 46295 | AS3: 46295 | AU3: N/a | BA3: Item | BB3: sites/ext-AonNFPIntegration/Lists/ITSM Integration InScope Inventory
A4: INT002 | B4: Integration | C4: BluePrint | D4: Javier | E4: 1.1 | F4: 1.1 | G4: Complete | H4: Complete | I4: In Progress | J4: Not Started | K4: Not Started | N4: Allows Blueprint users (NFP Member Firm users – external users) to create incidents for Blueprint issues they are facing. | O4: Bipin Sabhani, Shilpa Madduri (PM) | P4: Redesign | Q4: Redesign | R4: UAT In Progress | S4: 46232 | V4: STRY0146547 | W4: 46239 | AB4: • Bipin Sabhani • Shilpa Madduri | AE4: Complete | AF4: 46234 | AG4: 46227 | AH4: 46227 | AI4: Complete | AJ4: 46241 | AK4: 46241 | AL4: 46231 | AM4: Not Started | AN4: 46247 | AO4: 46247 | AP4: 46239 | AQ4: Not Started | AR4: 46295 | AS4: 46295 | AU4: N/a | BA4: Item | BB4: sites/ext-AonNFPIntegration/Lists/ITSM Integration InScope Inventory
A5: INT003 | B5: Integration | C5: NetOps Automation | D5: Javier | E5: 1.1 | F5: 1.1 | G5: Complete | H5: Complete | I5: Complete | J5: Done (08/31) | K5: Pending | L5: Pending Impln. | M5: Pending Impln. | N5: The NetBox application reads in records from the Site Code (u_site_code) table stored in ServiceNow | O5: Robert Spadaro, Ethan Katz | P5: Redesign | Q5: Redesign | R5: UAT In Progress | S5: 46220 | V5: STRY0146630 | W5: 46230 | AE5: Complete | AF5: 46234 | AG5: 46220 | AH5: 46220 | AI5: Complete | AJ5: 46241 | AK5: 46241 | AL5: 46227 | AM5: Not Started | AN5: 46247 | AO5: 46247 | AQ5: Not Started | AR5: 46295 | AS5: 46295 | AU5: N/a | BA5: Item | BB5: sites/ext-AonNFPIntegration/Lists/ITSM Integration InScope Inventory
A6: INT004 | B6: Integration | C6: NFP Cybersecurity | D6: N/a - Descoped | E6: N/a - Descoped | F6: N/a - Descoped | N6: Integrated with ServiceNow via a NFP Cybersecurity service account that creates incident records and manages them within ServiceNow via an automation, | O6: John Stratton | P6: Redesign | Q6: Retire / Descoped | R6: Descoped | Y6: Tim Lemm | AA6: Confirmed | AF6: 46234 | AM6: Not Started | AQ6: Not Started | AR6: 46295 | AS6: 46295 | AU6: N/a | BA6: Item | BB6: sites/ext-AonNFPIntegration/Lists/ITSM Integration InScope Inventory
A7: INT005 | B7: Integration | C7: Salesforce V2 Fingerprints | D7: Javier | E7: 1.1 | F7: 1.1 | G7: Complete | H7: Complete | I7: In Progress | J7: Not Started | K7: Not Started | L7: Not Received, Pending Implementation, Complete | M7: Not Received, Pending Implementation, Complete | N7: When an email is sent to the NFP ServiceNow instance with a certain ID in the subject line, an inbound email action (script within ServiceNow) creates a request using the Statement Mass Delete Catalog Item. | O7: Kris Lipetsky | P7: Redesign | Q7: Redesign | R7: UAT In Progress | S7: 46220 | U7: currently usingRMS RiskModeler | AR5858-QC001 as business_service later to be change to "Callidus ICM", Assignment Group is currently Global-Service Desk-Support, will later need to be changed to Benefits Commission Processing | V7: STRY0146532 | W7: 46230 | AB7: Rhoads McGuire - Kris Lipetzki | AE7: Complete | AF7: 46234 | AG7: 46216 | AH7: 46216 | AI7: Complete | AJ7: 46241 | AK7: 46241 | AL7: 46220 | AM7: Not Started | AN7: 46247 | AO7: 46247 | AP7: 46234 | AQ7: Not Started | AR7: 46295 | AS7: 46295 | AU7: N/a | BA7: Item | BB7: sites/ext-AonNFPIntegration/Lists/ITSM Integration InScope Inventory
A8: INT006 | B8: Integration | C8: PRTG | D8: N/a - Descoped | E8: N/a - Descoped | F8: N/a - Descoped | N8: Used for network monitoring, sending alerts / events to ServiceNow ITOM / EM | O8: Ethan Katz, Sagar Karur | P8: Redesign | Q8: Retire / Descoped | R8: Descoped | AA8: Confirmed | AF8: 46234 | AM8: Not Started | AQ8: Not Started | AR8: 46295 | AS8: 46295 | AU8: N/a | BA8: Item | BB8: sites/ext-AonNFPIntegration/Lists/ITSM Integration InScope Inventory
A9: INT007 | B9: Integration | C9: AD / Azure Data Factory | D9: Backlog | E9: 2.2 | F9: 2.2 | N9: *** Review Antowan's onboarding document for more details on this | O9: Antowan Jones | Q9: Redesign | R9: In Design | S9: 46262 | U9: As part of the onboarding/offboarding process, ServiceNow is integrated with AD. Technical POC: Khue Nguyen | W9: 46269 | AA9: Confirmed | AE9: In Progress | AF9: 46234 | AG9: 46241 | AI9: Not Started | AJ9: 46265 | AK9: 46265 | AM9: Not Started | AN9: 46268 | AO9: 46268 | AQ9: Not Started | AR9: 46295 | AS9: 46295 | AU9: Related to Onboarding & Transitions Order Guide | AV9: =TRUE() -> TRUE | BA9: Item | BB9: sites/ext-AonNFPIntegration/Lists/ITSM Integration InScope Inventory
A10: INT008 | B10: Integration | C10: Salesforce Back Office (SBO) | D10: Sowmya | E10: 1.1 | F10: 1.2 | G10: Complete | H10: Complete | I10: Not Started | J10: Not Started | K10: Not Started | L10: Not Started | M10: Not Started | N10: Related to Remote Work Request catalog item - integration needed as part of that workflow | O10: Jenna Davies | Q10: Redesign | R10: In Build Progress | S10: 46246 | W10: 46253 | AA10: N/A | AB10: Jenna Davies, Jerry Jenkins | AE10: Complete | AF10: 46234 | AG10: 46241 | AI10: In Progress | AJ10: 46241 | AK10: 46241 | AM10: In Progress | AN10: 46247 | AO10: 46247 | AQ10: Not Started | AR10: 46295 | AS10: 46295 | AU10: N/a | BA10: Item | BB10: sites/ext-AonNFPIntegration/Lists/ITSM Integration InScope Inventory
A11: INT009 | B11: Integration | C11: Azure (via Open Path flow) | D11: Sowmya | E11: 1.1 | F11: 1.2 | G11: Complete | H11: Complete | I11: In Progress | N11: API call to Azure / ADE once the Open Path catalog item is submitted (rather than a task generation) | O11: Anthony Papandrea | Q11: Redesign | R11: Ready for Testing | S11: 46246 | W11: 46253 | AA11: N/A | AB11: Chris Derico, Anthony Papandrea | AE11: In Progress | AF11: 46234 | AG11: 46241 | AI11: Complete | AJ11: 46241 | AK11: 46241 | AM11: Not Started | AN11: 46247 | AO11: 46247 | AQ11: Not Started | AR11: 46295 | AS11: 46295 | AU11: N/a | BA11: Item | BB11: sites/ext-AonNFPIntegration/Lists/ITSM Integration InScope Inventory
A12: PnC001 | B12: Catalog Item | C12: (P&C) Bank Account | D12: Somendra S.T. | E12: 3.1 | F12: 3.1 | O12: Teri C. | Q12: Redesign | R12: In Design | S12: 46288 | W12: 46295 | AA12: N/A | AU12: N/A | AV12: =FALSE() -> FALSE | BA12: Item | BB12: sites/ext-AonNFPIntegration/Lists/ITSM Integration InScope Inventory
A13: PnC002 | B13: Catalog Item | C13: (P&C) Broker and Carrier Billing Contact | D13: Somendra S.T. | E13: 3.1 | F13: 3.1 | O13: Teri C. | Q13: Redesign | R13: In Design | S13: 46288 | W13: 46295 | AA13: N/A | AU13: N/A | AV13: =FALSE() -> FALSE | BA13: Item | BB13: sites/ext-AonNFPIntegration/Lists/ITSM Integration InScope Inventory
A14: PnC003 | B14: Catalog Item | C14: (P&C) Document Design | D14: Somendra S.T. | E14: 3.1 | F14: 3.1 | O14: Teri C. | Q14: Redesign | R14: In Design | S14: 46288 | W14: 46295 | AA14: N/A | AU14: N/A | AV14: =FALSE() -> FALSE | BA14: Item | BB14: sites/ext-AonNFPIntegration/Lists/ITSM Integration InScope Inventory
A15: PnC004 | B15: Catalog Item | C15: (P&C) Download Resend/Discrepancy | D15: Somendra S.T. | E15: 3.1 | F15: 3.1 | O15: Teri C. | Q15: Redesign | R15: In Design | S15: 46288 | W15: 46295 | AA15: N/A | AU15: N/A | AV15: =FALSE() -> FALSE | BA15: Item | BB15: sites/ext-AonNFPIntegration/Lists/ITSM Integration InScope Inventory
A16: PnC005 | B16: Catalog Item | C16: (P&C) Employee Commission Agreement | D16: Somendra S.T. | E16: 3.1 | F16: 3.1 | O16: Teri C. | Q16: Redesign | R16: In Design | S16: 46288 | W16: 46295 | AA16: N/A | AU16: N/A | AV16: =FALSE() -> FALSE | BA16: Item | BB16: sites/ext-AonNFPIntegration/Lists/ITSM Integration InScope Inventory
A17: PnC006 | B17: Catalog Item | C17: (P&C) EMU Run Request | D17: Tarun | E17: 3.1 | F17: 3.1 | O17: Teri C. | Q17: Redesign | R17: In Design | S17: 46288 | W17: 46295 | AA17: N/A | AU17: N/A | AV17: =FALSE() -> FALSE | BA17: Item | BB17: sites/ext-AonNFPIntegration/Lists/ITSM Integration InScope Inventory
A18: PnC007 | B18: Catalog Item | C18: (P&C) Government Tax/Fee Request | D18: Somendra S.T. | E18: 3.1 | F18: 3.1 | O18: Teri C. | Q18: Redesign | R18: In Design | S18: 46288 | W18: 46295 | AA18: N/A | AU18: N/A | AV18: =FALSE() -> FALSE | BA18: Item | BB18: sites/ext-AonNFPIntegration/Lists/ITSM Integration InScope Inventory
A19: PnC008 | B19: Catalog Item | C19: (P&C) Issuing Company | D19: Somendra S.T. | E19: 3.1 | F19: 3.1 | O19: Teri C. | Q19: Redesign | R19: In Design | S19: 46288 | W19: 46295 | AA19: N/A | AU19: N/A | AV19: =FALSE() -> FALSE | BA19: Item | BB19: sites/ext-AonNFPIntegration/Lists/ITSM Integration InScope Inventory
A20: PnC009 | B20: Catalog Item | C20: (P&C) Opportunities | D20: Somendra S.T. | E20: 3.1 | F20: 3.1 | O20: Teri C. | Q20: Redesign | R20: In Design | S20: 46288 | W20: 46295 | AA20: N/A | AU20: N/A | AV20: =FALSE() -> FALSE | BA20: Item | BB20: sites/ext-AonNFPIntegration/Lists/ITSM Integration InScope Inventory
A21: PnC010 | B21: Catalog Item | C21: (P&C) Pathway Campaign Request | D21: Somendra S.T. | E21: 3.1 | F21: 3.1 | O21: Teri C | Q21: Redesign | R21: In Design | S21: 46288 | W21: 46295 | AA21: N/A | AU21: N/A | AV21: =FALSE() -> FALSE | BA21: Item | BB21: sites/ext-AonNFPIntegration/Lists/ITSM Integration InScope Inventory
A22: PnC011 | B22: Catalog Item | C22: (P&C) Reporting | D22: Somendra S.T. | E22: 3.1 | F22: 3.1 | O22: Teri C | Q22: Redesign | R22: In Design | S22: 46288 | W22: 46295 | AA22: N/A | AU22: N/A | AV22: =FALSE() -> FALSE | BA22: Item | BB22: sites/ext-AonNFPIntegration/Lists/ITSM Integration InScope Inventory
A23: PnC012 | B23: Catalog Item | C23: (P&C) User Report Access | D23: Somendra S.T. | E23: 3.1 | F23: 3.1 | O23: Teri C | Q23: Redesign | R23: In Design | S23: 46288 | W23: 46295 | AA23: N/A | AU23: N/A | AV23: =FALSE() -> FALSE | BA23: Item | BB23: sites/ext-AonNFPIntegration/Lists/ITSM Integration InScope Inventory
... A26: PnC015 | B26: Catalog Item | C26: (P&C) Applied P&C Applications User Request | D26: Descoped | E26: Descoped | F26: Descoped | O26: Teri C | Q26: Redesign | R26: Descoped | S26: 46288 | W26: 46295 | AA26: N/A | AU26: N/A | AV26: =FALSE() -> FALSE | BA26: Item | BB26: sites/ext-AonNFPIntegration/Lists/ITSM Integration InScope Inventory
A27: RM001 | B27: Catalog Item | C27: Create Request | D27: N/a - Descoped | E27: N/a - Descoped | F27: N/a - Descoped | N27: Create a Request for assistance | O27: Jerry Jenkins | P27: Redesign | Q27: Retire / Descoped | R27: Descoped | Z27: N/a - Descoped | AA27: Confirmed | AB27: Jerry Jenkins | AF27: 46234 | AJ27: 46241 | AK27: 46241 | AM27: Not Started | AN27: 46247 | AO27: 46247 | AQ27: Not Started | AR27: 46295 | AS27: 46295 | AU27: N/a | BA27: Item | BB27: sites/ext-AonNFPIntegration/Lists/ITSM Integration InScope Inventory
A28: RM002 | B28: Catalog Item | C28: Salesforce | D28: Sowmya | E28: 2.1 | F28: 2.1 | G28: Complete | H28: Complete | I28: In Progress | J28: Requested | N28: Create a request for Salesforce assistance. | O28: Kris Lipetsky | P28: Redesign | Q28: Redesign | R28: UAT In Progress | S28: 46255 | T28: Awaiting confirmation from Kris L. on NFP Salesforce application record (email out to Deepak B. and Simon S. on 7/7); Expected reply from Kris L. on 7/20 | U28: Kris to review current form design and provide PwC with updated design information on the Salesforce New User / Reactivate / PAM Record form | V28: STRY0147039 | W28: 46262 | Z28: July 6 | AE28: Complete | AF28: 46234 | AG28: 46234 | AI28: Complete | AJ28: 46255 | AK28: 46260 | AL28: 46260 | AM28: In Progress | AN28: 46261 | AO28: 46261 | AP28: 46265 | AQ28: Not Started | AR28: 46295 | AS28: 46295 | AU28: N/a | BA28: Item | BB28: sites/ext-AonNFPIntegration/Lists/ITSM Integration InScope Inventory
A29: RM003 | B29: Catalog Item | C29: Website Access Request | D29: Olivia | E29: 0 | F29: 0 | N29: Website Access Request | O29: Erryn Rodriguez | P29: Adopt | Q29: Adopt | R29: Adopt - No Build Needed | X29: Website Exception Request | Y29: Ajit Kumar Sharma | Z29: N/a - No design required | AE29: Complete | AF29: 46234 | AG29: 46234 | AH29: 46234 | AI29: Complete | AJ29: 46234 | AK29: 46234 | AL29: 46234 | AM29: Not Started | AN29: 46241 | AO29: 46241 | AQ29: Not Started | AR29: 46295 | AS29: 46295 | AU29: N/a | BA29: Item | BB29: sites/ext-AonNFPIntegration/Lists/ITSM Integration InScope Inventory
A30: RM004 | B30: Catalog Item | C30: NFP Financial Systems Assistance (Formally Concur) | D30: Tarun | E30: 1.2 | F30: 1.2 | G30: Complete | H30: In Progress | I30: Not Started | N30: Build new catalog item "NFP Financial Systems Assistance" to replace RM004 - Concur | O30: Bobbie Johnson | P30: Adapt | Q30: Redesign | R30: Ready for Testing | S30: 46248 | U30: Scope change confirmed 7/13 | W30: 46254 | X30: Application Generic Service Request | Y30: Simon Sankey | Z30: N/a - No follow ups from survey at this time | AA30: Confirmed | AB30: Kelly Cecchini, Nancy Govea | AE30: In Progress | AF30: 46234 | AG30: 46234 | AH30: 46234 | AI30: In Progress | AJ30: 46248 | AK30: 46254 | AL30: 46254 | AM30: In Progress | AN30: 46260 | AO30: 46260 | AQ30: Not Started | AR30: 46295 | AS30: 46295 | AU30: Available alone and in O&T OG | AV30: =TRUE() -> TRUE | BA30: Item | BB30: sites/ext-AonNFPIntegration/Lists/ITSM Integration InScope Inventory
A31: RM005 | B31: Catalog Item | C31: Remote Work Request | D31: Sowmya | E31: 1.1 | F31: 1.2 | G31: Complete | H31: Complete | I31: Not Started | J31: Not Started | K31: Not Started | L31: Not Started | M31: Not Started | N31: Create a Request to be allowed to work remotely. | O31: Jenna Davies, John Stratton | P31: Adopt | Q31: Redesign | R31: On Hold | S31: 46246 | W31: 46253 | X31: Aon Remote Access | Y31: Soumendu Kumar Singh | AA31: Confirmed | AE31: In Progress | AF31: 46234 | AG31: 46241 | AI31: Not Started | AJ31: 46248 | AK31: 46248 | AM31: Not Started | AN31: 46254 | AO31: 46254 | AQ31: Not Started | AR31: 46295 | AS31: 46295 | AU31: N/a | BA31: Item | BB31: sites/ext-AonNFPIntegration/Lists/ITSM Integration InScope Inventory
A32: RM006 | B32: Catalog Item | C32: EPIC | D32: N/a - Descoped | E32: N/a - Descoped | F32: N/a - Descoped | N32: Create a request for EPIC assistance. | O32: Teri Cote | P32: Redesign | Q32: Retire / Descoped | R32: Descoped | U32: Confirmed not needed by Teri via questionnaire email response on 25-Jun. Confirmed by Frank 7/13. | Z32: July 15 | AA32: Confirmed | AF32: 46234 | AJ32: 46255 | AK32: 46255 | AM32: Not Started | AN32: 46261 | AO32: 46261 | AQ32: Not Started | AR32: 46295 | AS32: 46295 | AU32: N/a | AV32: =TRUE() -> TRUE | BA32: Item | BB32: sites/ext-AonNFPIntegration/Lists/ITSM Integration InScope Inventory
A33: RM007 | B33: Catalog Item | C33: Onboarding and Transitions - Egnyte | D33: N/a - Descoped | E33: N/a - Descoped | F33: N/a - Descoped | N33: Create a request for Egnyte assistance | O33: Giovanni Scrima | P33: Redesign | Q33: Retire / Descoped | R33: Descoped | U33: Confirmed that Egnyte does not need to be recreated within the Onboarding & Transitions order guide. Non-onboarding related requests will route through Aon's existing intake paths; Generic Application Service Request. | Z33: July 6 | AA33: Confirmed | AF33: 46234 | AJ33: 46241 | AK33: 46241 | AM33: Not Started | AN33: 46247 | AO33: 46247 | AQ33: Not Started | AR33: 46295 | AS33: 46295 | AU33: N/a | AV33: =TRUE() -> TRUE | BA33: Item | BB33: sites/ext-AonNFPIntegration/Lists/ITSM Integration InScope Inventory
A34: RM008 | B34: Catalog Item | C34: Active Directory Orchestration | D34: Javier | E34: 1.1 | F34: 2.1 | N34: Active Directory Orchestration | O34: Antowan Jones | P34: Redesign | Q34: Redesign | R34: In Build Progress | S34: 46241 | V34: STRY0146932 | W34: 46246 | Z34: June 26 | AB34: Donald Barksdale, Antowan Jones | AE34: Complete | AF34: 46234 | AG34: 46220 | AH34: 46220 | AI34: Complete | AJ34: 46241 | AK34: 46241 | AM34: Not Started | AN34: 46247 | AO34: 46247 | AQ34: Not Started | AR34: 46295 | AS34: 46295 | AU34: Only available in O&T OG | AV34: =TRUE() -> TRUE | AX34: Yes | BA34: Item | BB34: sites/ext-AonNFPIntegration/Lists/ITSM Integration InScope Inventory
A35: RM009 | B35: Catalog Item | C35: AD Account and Mailbox/Calendar Setup Offboarding | D35: Backlog | E35: 2.2 | F35: 2.2 | N35: AD Account and Mailbox/Calendar Setup Offboarding | O35: Donald Barksdale | P35: Redesign | Q35: Redesign | R35: In Design | S35: 46258 | U35: Awaiting Scope Confirmation Changes (AD Integration) | W35: 46262 | Z35: July 7 | AB35: Donald Barksdale, Nick Pilisko, Stephanie Lujan, Michael Kruger | AE35: In Progress | AF35: 46234 | AG35: 46241 | AI35: Not Started | AJ35: 46265 | AK35: 46265 | AM35: Not Started | AN35: 46268 | AO35: 46268 | AQ35: Not Started | AR35: 46295 | AS35: 46295 | AU35: Only available in O&T OG | AV35: =TRUE() -> TRUE | AX35: Yes | BA35: Item | BB35: sites/ext-AonNFPIntegration/Lists/ITSM Integration InScope Inventory
A36: RM010 | B36: Catalog Item | C36: Request Hardware | D36: N/a - Descoped | E36: N/a - Descoped | F36: N/a - Descoped | N36: Request New Computer or Peripheral. | O36: Ethan Katz | P36: Adopt | Q36: Retire / Descoped | R36: Descoped | U36: Retire. Replaced by AON's existing "Hardware Systems and Applications Access" order guide (Hardware & Peripherals path). | X36: Hardware, Systems & Application Access | Y36: Simon Sankey | Z36: July 9 | AA36: Confirmed | AF36: 46234 | AJ36: 46255 | AK36: 46255 | AM36: Not Started | AN36: 46261 | AO36: 46261 | AQ36: Not Started | AR36: 46295 | AS36: 46295 | AU36: N/a | BA36: Item | BB36: sites/ext-AonNFPIntegration/Lists/ITSM Integration InScope Inventory
A37: RM011 | B37: Catalog Item | C37: NFP Phone System - Termination | D37: Tarun | E37: 2.1 | F37: 2.1 | N37: Backend item: NFP Phone System termination/offboarding | O37: Kim Ragland | P37: Redesign | Q37: Redesign | R37: Not Started | S37: 46251 | W37: 46258 | Z37: July 14 | AE37: In Progress | AF37: 46234 | AG37: 46234 | AI37: Not Started | AJ37: 46255 | AK37: 46255 | AM37: Not Started | AN37: 46261 | AO37: 46261 | AQ37: Not Started | AR37: 46295 | AS37: 46295 | AU37: Only available in O&T OG | AV37: =TRUE() -> TRUE | BA37: Item | BB37: sites/ext-AonNFPIntegration/Lists/ITSM Integration InScope Inventory
A38: RM012 | B38: Catalog Item | C38: Salesforce Policy Update | D38: Olivia | E38: 1.1 | F38: 1.1 | G38: Complete | H38: Complete | I38: Complete | J38: Done (08/31) | K38: Confirmed (08/31) | N38: Request to update a Salesforce policy | O38: Andrew Howard | P38: Redesign | Q38: Redesign | R38: UAT In Progress | S38: 46227 | V38: STRY0146814 | W38: 46234 | Z38: July 6 | AD38: Build shell completed - ready for test script creation Placeholders still in place for: Assignment Group, Catalog Location | AF38: 46234 | AG38: 46209 | AH38: 46209 | AI38: Complete | AJ38: 46241 | AK38: 46241 | AL38: 46230 | AM38: In Progress | AN38: 46247 | AO38: 46247 | AQ38: Not Started | AR38: 46295 | AS38: 46295 | AU38: N/a | AW38: Placeholder Assignment Group for testing | BA38: Item | BB38: sites/ext-AonNFPIntegration/Lists/ITSM Integration InScope Inventory
A39: RM013 | B39: Catalog Item | C39: AD Account and Mailbox/Calendar Setup | D39: Backlog | E39: 2.2 | F39: 2.2 | N39: AD Account and Mailbox/Calendar Setup | O39: Donald Barksdale | P39: Redesign | Q39: Redesign | R39: In Design | S39: 46258 | U39: Part of NFP On/offboarding Order Guide; Need to scope with Frank's team upon follow up with Antowan on AD integration scope. | W39: 46262 | Z39: July 7 | AB39: Donald Barksdale, Nick Pilisko, Stephanie Lujan, Michael Kruger | AE39: In Progress | AF39: 46234 | AG39: 46241 | AI39: Not Started | AJ39: 46265 | AK39: 46265 | AM39: Not Started | AN39: 46268 | AO39: 46268 | AQ39: Not Started | AR39: 46295 | AS39: 46295 | AU39: Only available in O&T OG | AV39: =TRUE() -> TRUE | AX39: Yes | BA39: Item | BB39: sites/ext-AonNFPIntegration/Lists/ITSM Integration InScope Inventory
A40: RM014 | B40: Catalog Item | C40: Financial Applications | D40: N/a - Descoped | E40: N/a - Descoped | F40: N/a - Descoped | N40: Financial Applications | O40: Tyler Webber | P40: Redesign | Q40: Retire / Descoped | R40: Descoped | U40: Part of NFP On/offboarding Order Guide; Antowan to confirm whether financial apps remain in the onboarding and transitions guide | Z40: July 13 | AF40: 46234 | AJ40: 46248 | AK40: 46248 | AM40: Not Started | AN40: 46254 | AO40: 46254 | AQ40: Not Started | AR40: 46295 | AS40: 46295 | AU40: N/a | BA40: Item | BB40: sites/ext-AonNFPIntegration/Lists/ITSM Integration InScope Inventory
A41: RM015 | B41: Catalog Item | C41: Onboarding DocuSign | D41: Olivia | E41: 1.1 | F41: 1.1 | G41: Complete | H41: Complete | I41: Complete | J41: Done (08/31) | K41: Pending | L41: Pending Impln. | M41: Pending Impln. | N41: Create a request for DocuSign assistance | O41: Tony Nicosia | P41: Redesign | Q41: Redesign | R41: UAT In Progress | S41: 46241 | U41: Part of NFP On/offboarding Order Guide | V41: STRY0146965 | W41: 46248 | Z41: July 7 | AB41: Brian English, Tony Nicosia | AE41: Complete | AF41: 46234 | AG41: 46213 | AH41: 46213 | AI41: Complete | AJ41: 46241 | AK41: 46241 | AL41: 46241 | AM41: In Progress | AN41: 46247 | AO41: 46247 | AQ41: Not Started | AR41: 46295 | AS41: 46295 | AU41: Available alone and in O&T OG | AV41: =TRUE() -> TRUE | AW41: Assignment Group - confirm what it should be during UAT, Order Guide Linkage | AX41: Yes | BA41: Item | BB41: sites/ext-AonNFPIntegration/Lists/ITSM Integration InScope Inventory
A42: RM016 | B42: Catalog Item | C42: OneDrive Access | D42: Olivia | E42: 1.2 | F42: 1.2 | G42: Complete | H42: Complete | I42: Not Started | J42: Not Started | K42: Not Started | N42: OneDrive Access | O42: Brian English | P42: Adopt | Q42: Redesign | R42: Ready for Testing | S42: 46248 | U42: Original disposition: Adopt (assumed Aon's existing OneDrive access request would cover NFP needs) Updated disposition: Redesign, A standalone NFP OneDrive catalog item is needed, separate from Aon's, since users are on a dual tenant and some staff will need both Aon and NFP OneDrive access. Confirmed details: No automation/integrations tied to this request access is granted manually through manager approval. Fulfilled by Brian's SharePoint team; this assignment group will carry over to the Aon environment. Next step: Disposition change (adopt to redesign) will be documented in the scope change log. | V42: STRY0147007 | W42: 46255 | X42: Hardware, Systems & Application Access | Y42: Simon Sankey | Z42: Application Related? | AE42: Complete | AF42: 46234 | AG42: 46213 | AH42: 46213 | AI42: Complete | AJ42: 46248 | AK42: 46248 | AL42: 46248 | AM42: Not Started | AN42: 46254 | AO42: 46254 | AQ42: Not Started | AR42: 46295 | AS42: 46295 | AU42: Only available in O&T OG | AV42: =TRUE() -> TRUE | AW42: TIMERS are INCORRECT - shortened for testing purposes only. | AX42: Yes | BA42: Item | BB42: sites/ext-AonNFPIntegration/Lists/ITSM Integration InScope Inventory
...

Sheet Instructions
A1: Nitin Shetty (US) Sowmya M R (US) I created a separate tab for AG Mapping, AG Inventory, and Group Membership. Instruction on how to populate: Confirm the group names and group manager + members with the NFP Owner Go into the tracker and navigate to "Assignment Group Inventory" tab Check if the group you want to add already created If not created, add the Assignment Group Name to the next free AG ID, and populate Manager's name; Ensure adherence to the Aon naming standard; pay attention to Approval and Support groups, and name your groups according to the use case If created, grab the AG ID Navigate to the AG Mapping to Items tab: Find the Target Aon Catalog Item in column C that your group needs to be used for Populate the grabbed AG ID into the AG ID column If multiple groups are in the workflow, add new line item on the tab, and populate the AON ID in the newly created line item, it will pull the Target Aon Catalog Item name, and then populate the next AG ID in that line, populate manager Navigate to Group Membership tab Populate the grabbed AG ID into the new line item Each line item = one group member Populate group members

Sheet AGs to Create in PROD+TEST+DEV
A1: AG ID | B1: Assignment Group Name | C1: Group Manager | D1: Manager's Email | E1: Short Description | F1: Service | G1: Prod | H1: Test | I1: Dev
A2: AG001 | B2: Global-NFP AI Working Group-Approval | C2: Sulyman Al-Ani | D2: sulyman.alani@nfp.co.uk | E2: Approval group for the following catalog item deployed as part of NFP integration: NFP - AI Governance Review | F2: NFP
A3: AG002 | B3: Global-NFP Amex Card Management-Support | C3: Kelly Cecchini | D3: kelly.cecchini@nfp.com | E3: Support group for the following catalog item deployed as part of NFP integration: NFP - Amex Purchase Card Application Form | F3: NFP
A4: AG003 | B4: Global-NFP Application Engineering-Support | C4: Shashank Karanje | D4: shashank.karanje@nfp.com | E4: Support group to be deployed as part of NFP integration. Support group to receive incident tickets as part of NFP Blueprint and NFP Connect Integrations | F4: NFP
A5: AG004 | B5: Global-NFP Azure DevOps Engineering-Support | C5: Frank Natividad | D5: frank.natividad@nfp.com | E5: Support group for the following catalog item deployed as part of NFP integration: NFP - DevOps Support | F5: NFP
A6: AG005 | B6: Global-NFP Benefits Commission Processing-Support | C6: Kris Lipetzky | D6: klipetzky@nfp.com | E6: Support group for the following catalog item deployed as part of NFP integration: NFP - Carrier Statement Mass Delete Request, NFP - Producer Additions & Terminations, NFP - Salesforce Policy Update | F6: NFP
A7: AG007 | B7: Global-NFP CRM Services-Support | C7: Kris Lipetzky | D7: klipetzky@nfp.com | E7: Support group for the following catalog item deployed as part of NFP integration: NFP - Application Users List Generation for Email Rebrand, NFP - Producer Additions & Terminations, NFP - Return from LOA, NFP - Salesforce Access Request, NFP - SBO Request for Onboarding | F7: NFP
A8: AG009 | B8: Global-NFP CyberSecurity-Support | C8: John Stratton | D8: john.stratton@nfp.com | E8: Support group for the following catalog item deployed as part of NFP integration: NFP - Remote Work Request | F8: NFP
A9: AG012 | B9: Global-NFP Go Anywhere SFTP-Support | C9: Enoch Tong | D9: etong@nfp.com | E9: Support group for the following catalog item deployed as part of NFP integration: NFP - Go Anywhere Request | F9: NFP
A10: AG013 | B10: Global-NFP Time Tracker-Support | C10: Kirk Oswalt | D10: kirk.oswalt@nfp.com | E10: Support group for the following catalog item deployed as part of NFP integration: NFP - Time Tracker | F10: NFP
A11: AG015 | B11: Global-NFP P&C-App-Support | C11: Teri Cote | D11: teri.cote@nfp.com | E11: Support group for the following catalog item deployed as part of NFP integration: NFP - Name / Email Change Request, NFP - Return from LOA | F11: NFP
A12: AG016 | B12: Global-NFP Plan Document-Support | C12: Chase Cannon | D12: ccannon@nfp.com | E12: Support group for the following catalog item deployed as part of NFP integration: NFP - Plan Document Request | F12: NFP
A13: AG023 | B13: Global-NFP Technology Logistics-Support | C13: Kimberley Ragland | D13: kragland@nfp.com | E13: Support group for the following catalog item deployed as part of NFP integration: NFP - Hardware Return, NFP - Onboarding Hardware Request | F13: NFP
... A40: AG058 | B40: Global-NFP Third Party Access-Approval | C40: Steve Chapman | D40: schapman@nfp.com | E40: Approval group for the following catalog item deployed as part of NFP integration: NFP - Technology Third Party Users Access | F40: NFP

Sheet AGs to Create in TEST+DEV
A1: AG ID | B1: Assignment Group Name | C1: Group Manager | D1: Prod | E1: Test | F1: Dev
A2: AG011 | B2: Global-NFP Financial Systems-Support | C2: Bobbie Johnson | D2: Created | E2: Not Created | F2: Not Created
A3: AG014 | B3: Global-NFP Networks-Support | C3: Robert Spadaro | D3: Created | E3: Not Created | F3: Not Created
A4: AG019 | B4: Global-NFP Service Desk Tier 1-Support | C4: Nick Pilisko | D4: Created | E4: Not Created | F4: Not Created
A5: AG021 | B5: Global-NFP Service Desk Tier 3 Core Services-Support | C5: Steve Chapman | D5: Created | E5: Not Created | F5: Not Created
A6: AG022 | B6: Global-NFP ServiceNow-Support | C6: Antowan Jones | D6: Created | E6: Not Created | F6: Not Created
A7: AG032 | B7: Global-NFP Data Management-Support | C7: Antowan Jones | D7: Created | E7: Not Created | F7: Not Created
A8: AG037 | B8: Global-NFP MGA-Support | C8: Regina Riedel | D8: Created | E8: Not Created | F8: Not Created

Sheet Group Membership
A1: AG ID | B1: Assignment Group Name | C1: First Name | D1: Last Name | E1: Email
A2: AG001 | B2: Global-NFP AI Working Group-Approval | C2: Sulyman | D2: Al-Ani | E2: sulyman.alani@nfp.co.uk
A3: AG001 | B3: Global-NFP AI Working Group-Approval | C3: Mark | D3: Grosvenor | E3: mark.grosvenor@nfp.com
A4: AG001 | B4: Global-NFP AI Working Group-Approval | C4: Tom | D4: Claridge | E4: tom.claridge@nfp.co.uk
A5: AG001 | B5: Global-NFP AI Working Group-Approval | C5: David | D5: Horn | E5: dhorn@nfp.com
A6: AG001 | B6: Global-NFP AI Working Group-Approval | C6: James | D6: Fritz | E6: james.fritz@nfp.com
A7: AG001 | B7: Global-NFP AI Working Group-Approval | C7: Jayaprakash | D7: Subramaniam | E7: jsubramaniam@nfp.com
A8: AG002 | B8: Global-NFP Amex Card Management-Support | C8: Eugene | D8: Melino | E8: emelino@nfp.com
A9: AG002 | B9: Global-NFP Amex Card Management-Support | C9: Kelly | D9: Cecchini | E9: kelly.cecchini@nfp.com
A10: AG002 | B10: Global-NFP Amex Card Management-Support | C10: Nancy | D10: Govea | E10: nancy.govea@nfp.com
A11: AG002 | B11: Global-NFP Amex Card Management-Support | C11: Megan | D11: Goad | E11: megan.goad@nfp.com
A12: AG003 | B12: Global-NFP Application Engineering-Support | C12: Balajiprasad | D12: Ramesh | E12: bramesh@nfp.com
... A499: AG058 | B499: Global-NFP Third Party Access-Approval | C499: Tomson | D499: John | E499: tomson.john@nfp.com
B501: =IF($A501="","",IFERROR(IF(INDEX('AGs to Create in TEST+DEV'!$B$2:$B$220,MATCH($A501,'AGs to Create in TEST+DEV'!$A$2:$A$220,0))="","",INDEX('AGs to Create in TEST+DEV'!$B$2:$B$220,MATCH($A501,'AGs to Create in TEST+DEV'!$A$2:$A$220,0))),"Not in inventory"))
B502: =IF($A502="","",IFERROR(IF(INDEX('AGs to Create in TEST+DEV'!$B$2:$B$220,MATCH($A502,'AGs to Create in TEST+DEV'!$A$2:$A$220,0))="","",INDEX('AGs to Create in TEST+DEV'!$B$2:$B$220,MATCH($A502,'AGs to Create in TEST+DEV'!$A$2:$A$220,0))),"Not in inventory"))
B503: =IF($A503="","",IFERROR(IF(INDEX('AGs to Create in TEST+DEV'!$B$2:$B$220,MATCH($A503,'AGs to Create in TEST+DEV'!$A$2:$A$220,0))="","",INDEX('AGs to Create in TEST+DEV'!$B$2:$B$220,MATCH($A503,'AGs to Create in TEST+DEV'!$A$2:$A$220,0))),"Not in inventory"))
B504: =IF($A504="","",IFERROR(IF(INDEX('AGs to Create in TEST+DEV'!$B$2:$B$220,MATCH($A504,'AGs to Create in TEST+DEV'!$A$2:$A$220,0))="","",INDEX('AGs to Create in TEST+DEV'!$B$2:$B$220,MATCH($A504,'AGs to Create in TEST+DEV'!$A$2:$A$220,0))),"Not in inventory"))
B505: =IF($A505="","",IFERROR(IF(INDEX('AGs to Create in TEST+DEV'!$B$2:$B$220,MATCH($A505,'AGs to Create in TEST+DEV'!$A$2:$A$220,0))="","",INDEX('AGs to Create in TEST+DEV'!$B$2:$B$220,MATCH($A505,'AGs to Create in TEST+DEV'!$A$2:$A$220,0))),"Not in inventory"))
B506: =IF($A506="","",IFERROR(IF(INDEX('AGs to Create in TEST+DEV'!$B$2:$B$220,MATCH($A506,'AGs to Create in TEST+DEV'!$A$2:$A$220,0))="","",INDEX('AGs to Create in TEST+DEV'!$B$2:$B$220,MATCH($A506,'AGs to Create in TEST+DEV'!$A$2:$A$220,0))),"Not in inventory"))
B507: =IF($A507="","",IFERROR(IF(INDEX('AGs to Create in TEST+DEV'!$B$2:$B$220,MATCH($A507,'AGs to Create in TEST+DEV'!$A$2:$A$220,0))="","",INDEX('AGs to Create in TEST+DEV'!$B$2:$B$220,MATCH($A507,'AGs to Create in TEST+DEV'!$A$2:$A$220,0))),"Not in inventory"))
B508: =IF($A508="","",IFERROR(IF(INDEX('AGs to Create in TEST+DEV'!$B$2:$B$220,MATCH($A508,'AGs to Create in TEST+DEV'!$A$2:$A$220,0))="","",INDEX('AGs to Create in TEST+DEV'!$B$2:$B$220,MATCH($A508,'AGs to Create in TEST+DEV'!$A$2:$A$220,0))),"Not in inventory"))
B509: =IF($A509="","",IFERROR(IF(INDEX('AGs to Create in TEST+DEV'!$B$2:$B$220,MATCH($A509,'AGs to Create in TEST+DEV'!$A$2:$A$220,0))="","",INDEX('AGs to Create in TEST+DEV'!$B$2:$B$220,MATCH($A509,'AGs to Create in TEST+DEV'!$A$2:$A$220,0))),"Not in inventory"))
B510: =IF($A510="","",IFERROR(IF(INDEX('AGs to Create in TEST+DEV'!$B$2:$B$220,MATCH($A510,'AGs to Create in TEST+DEV'!$A$2:$A$220,0))="","",INDEX('AGs to Create in TEST+DEV'!$B$2:$B$220,MATCH($A510,'AGs to Create in TEST+DEV'!$A$2:$A$220,0))),"Not in inventory"))
B511: =IF($A511="","",IFERROR(IF(INDEX('AGs to Create in TEST+DEV'!$B$2:$B$220,MATCH($A511,'AGs to Create in TEST+DEV'!$A$2:$A$220,0))="","",INDEX('AGs to Create in TEST+DEV'!$B$2:$B$220,MATCH($A511,'AGs to Create in TEST+DEV'!$A$2:$A$220,0))),"Not in inventory"))
B512: =IF($A512="","",IFERROR(IF(INDEX('AGs to Create in TEST+DEV'!$B$2:$B$220,MATCH($A512,'AGs to Create in TEST+DEV'!$A$2:$A$220,0))="","",INDEX('AGs to Create in TEST+DEV'!$B$2:$B$220,MATCH($A512,'AGs to Create in TEST+DEV'!$A$2:$A$220,0))),"Not in inventory"))
... B526: =IF($A526="","",IFERROR(IF(INDEX('AGs to Create in TEST+DEV'!$B$2:$B$220,MATCH($A526,'AGs to Create in TEST+DEV'!$A$2:$A$220,0))="","",INDEX('AGs to Create in TEST+DEV'!$B$2:$B$220,MATCH($A526,'AGs to Create in TEST+DEV'!$A$2:$A$220,0))),"Not in inventory"))

Sheet ASSIGNMENT GROUPS
C3: Number | D3: Item Name | E3: RITM Number | F3: ASSIGNMENT GROUP NAME | G3: Status | H3: PwC Owner | I3: Cloned Down | J3: ITIL Assigned
F4: RITM5301885: Global-Financial Systems-Support
F6: RITM5302297: Global-Amex Card Management-Support
F8: RITM5299949: Global-CRM Services-Support
F10: RITM5299934: Global-Plan Doc-Support
F12: RITM5307167: Global-Azure DevOps Engineering-Support
F14: RITM5307160 : Global-Quality Assurance Infrastructure-Support
F16: RITM5294435: Global-Service Desk Tier 3 Core Services-Support
F18: RITM5294404: Global-NFP Networks-Support
F20: RITM5294415: Global-NFP Data Management-Support
